Traceback (most recent call last):
  File "/Users/dorme/.pyenv/versions/3.7.7/lib/python3.7/site-packages/jupyter_cache/executors/utils.py", line 56, in single_nb_execution
    record_timing=False,
  File "/Users/dorme/.pyenv/versions/3.7.7/lib/python3.7/site-packages/nbclient/client.py", line 1087, in execute
    return NotebookClient(nb=nb, resources=resources, km=km, **kwargs).execute()
  File "/Users/dorme/.pyenv/versions/3.7.7/lib/python3.7/site-packages/nbclient/util.py", line 74, in wrapped
    return just_run(coro(*args, **kwargs))
  File "/Users/dorme/.pyenv/versions/3.7.7/lib/python3.7/site-packages/nbclient/util.py", line 53, in just_run
    return loop.run_until_complete(coro)
  File "/Users/dorme/.pyenv/versions/3.7.7/lib/python3.7/asyncio/base_events.py", line 587, in run_until_complete
    return future.result()
  File "/Users/dorme/.pyenv/versions/3.7.7/lib/python3.7/site-packages/nbclient/client.py", line 541, in async_execute
    cell, index, execution_count=self.code_cells_executed + 1
  File "/Users/dorme/.pyenv/versions/3.7.7/lib/python3.7/site-packages/nbclient/client.py", line 832, in async_execute_cell
    self._check_raise_for_error(cell, exec_reply)
  File "/Users/dorme/.pyenv/versions/3.7.7/lib/python3.7/site-packages/nbclient/client.py", line 740, in _check_raise_for_error
    raise CellExecutionError.from_cell_and_msg(cell, exec_reply['content'])
nbclient.exceptions.CellExecutionError: An error occurred while executing the following cell:
------------------
# Drop the patch data and landscape rows
lsm_forest <- subset(lsm, level == 'class')
# Drop down to the forest class and also reduce to the three core fields
lsm_forest <- subset(lsm_forest, class == 1, select=c(metric, value, plot_id))

# Rename the value field so that - when combined with the metric
# name - the local landscape details are recorded
names(lsm_forest)[2] <- 'C600'

# Reshape that dataset so that each metric has its own column
lsm_forest <- reshape(data.frame(lsm_forest), direction='wide', 
                      timevar='metric', idvar='plot_id')
print(lsm_forest, n=10)
------------------

Error in print.default(m, ..., quote = quote, right = right, max = max): invalid 'na.print' specification
Traceback:

1. print(lsm_forest, n = 10)
2. print(lsm_forest, n = 10)
3. print.data.frame(lsm_forest, n = 10)
4. print(m, ..., quote = quote, right = right, max = max)
5. print.default(m, ..., quote = quote, right = right, max = max)
ERROR: Error in print.default(m, ..., quote = quote, right = right, max = max): invalid 'na.print' specification


