Traceback (most recent call last):
  File "/Users/dorme/.pyenv/versions/3.7.7/lib/python3.7/site-packages/jupyter_cache/executors/utils.py", line 56, in single_nb_execution
    record_timing=False,
  File "/Users/dorme/.pyenv/versions/3.7.7/lib/python3.7/site-packages/nbclient/client.py", line 1087, in execute
    return NotebookClient(nb=nb, resources=resources, km=km, **kwargs).execute()
  File "/Users/dorme/.pyenv/versions/3.7.7/lib/python3.7/site-packages/nbclient/util.py", line 74, in wrapped
    return just_run(coro(*args, **kwargs))
  File "/Users/dorme/.pyenv/versions/3.7.7/lib/python3.7/site-packages/nbclient/util.py", line 53, in just_run
    return loop.run_until_complete(coro)
  File "/Users/dorme/.pyenv/versions/3.7.7/lib/python3.7/asyncio/base_events.py", line 587, in run_until_complete
    return future.result()
  File "/Users/dorme/.pyenv/versions/3.7.7/lib/python3.7/site-packages/nbclient/client.py", line 541, in async_execute
    cell, index, execution_count=self.code_cells_executed + 1
  File "/Users/dorme/.pyenv/versions/3.7.7/lib/python3.7/site-packages/nbclient/client.py", line 832, in async_execute_cell
    self._check_raise_for_error(cell, exec_reply)
  File "/Users/dorme/.pyenv/versions/3.7.7/lib/python3.7/site-packages/nbclient/client.py", line 740, in _check_raise_for_error
    raise CellExecutionError.from_cell_and_msg(cell, exec_reply['content'])
nbclient.exceptions.CellExecutionError: An error occurred while executing the following cell:
------------------
# Predict from the same model but using the future data
bioclim_pred_2050 <- predict(bioclim_2050_local, bioclim_model)
# Apply the same threshold
tapir_range_2050 <- bioclim_pred_2050 >= max_kappa

par(mfrow=c(1,3))
plot(tapir_range, legend=FALSE, col=c('grey','red'))
plot(tapir_range_2050, legend=FALSE, col=c('grey','red')))

# This is a bit of a hack - adding 2 * hist + 2050 gives:
# 0 + 0 - present in neither model
# 0 + 1 - only in future
# 2 + 0 - only in hist
# 2 + 1 - in both
tapir_change <- 2 * (tapir_range) + tapir_range_2050
cols <- c('lightgrey', 'blue', 'red', 'grey30')
plot(tapir_change, col=cols, legend=FALSE)
legend('topleft', fill=cols, legend=c('Absent','Future','Historical', 'Both'), bg='white')
------------------

Error in parse(text = x, srcfile = src): <text>:8:58: unexpected ')'
7: plot(tapir_range, legend=FALSE, col=c('grey','red'))
8: plot(tapir_range_2050, legend=FALSE, col=c('grey','red')))
                                                            ^
Traceback:

ERROR: Error in parse(text = x, srcfile = src): <text>:8:58: unexpected ')'
7: plot(tapir_range, legend=FALSE, col=c('grey','red'))
8: plot(tapir_range_2050, legend=FALSE, col=c('grey','red')))
                                                            ^


