Traceback (most recent call last):
  File "/Users/dorme/.pyenv/versions/3.7.7/lib/python3.7/site-packages/jupyter_cache/executors/utils.py", line 56, in single_nb_execution
    record_timing=False,
  File "/Users/dorme/.pyenv/versions/3.7.7/lib/python3.7/site-packages/nbclient/client.py", line 1087, in execute
    return NotebookClient(nb=nb, resources=resources, km=km, **kwargs).execute()
  File "/Users/dorme/.pyenv/versions/3.7.7/lib/python3.7/site-packages/nbclient/util.py", line 74, in wrapped
    return just_run(coro(*args, **kwargs))
  File "/Users/dorme/.pyenv/versions/3.7.7/lib/python3.7/site-packages/nbclient/util.py", line 53, in just_run
    return loop.run_until_complete(coro)
  File "/Users/dorme/.pyenv/versions/3.7.7/lib/python3.7/asyncio/base_events.py", line 587, in run_until_complete
    return future.result()
  File "/Users/dorme/.pyenv/versions/3.7.7/lib/python3.7/site-packages/nbclient/client.py", line 541, in async_execute
    cell, index, execution_count=self.code_cells_executed + 1
  File "/Users/dorme/.pyenv/versions/3.7.7/lib/python3.7/site-packages/nbclient/client.py", line 832, in async_execute_cell
    self._check_raise_for_error(cell, exec_reply)
  File "/Users/dorme/.pyenv/versions/3.7.7/lib/python3.7/site-packages/nbclient/client.py", line 740, in _check_raise_for_error
    raise CellExecutionError.from_cell_and_msg(cell, exec_reply['content'])
nbclient.exceptions.CellExecutionError: An error occurred while executing the following cell:
------------------
sea_pal <- colorRampPalette(c('grey30', 'grey50', 'grey70'))
plot(so_topo, col=sea_pal(100), asp=1, legend=FALSE)
contour(so_topo, levels=c(-2000, -4000, -6000), add=TRUE, col='grey80')
plot(st_geometry(so_ne_10), add=TRUE, col='grey90', border='grey40')
plot(so_data['chlorophyll'], add=TRUE, logz=TRUE, pch=20, cex=2, pal=viridis, border='white', reset=FALSE)
.image_scale(log10(so_data$chlorophyll), col=hcl.colors(18), key.length=0.8, key.pos=4, logz=TRUE)
------------------

Error in plot.sf(so_data["chlorophyll"], add = TRUE, logz = TRUE, pch = 20, : object 'viridis' not found
Traceback:

1. plot(so_data["chlorophyll"], add = TRUE, logz = TRUE, pch = 20, 
 .     cex = 2, pal = viridis, border = "white", reset = FALSE)
2. plot(so_data["chlorophyll"], add = TRUE, logz = TRUE, pch = 20, 
 .     cex = 2, pal = viridis, border = "white", reset = FALSE)
3. plot.sf(so_data["chlorophyll"], add = TRUE, logz = TRUE, pch = 20, 
 .     cex = 2, pal = viridis, border = "white", reset = FALSE)
ERROR: Error in plot.sf(so_data["chlorophyll"], add = TRUE, logz = TRUE, pch = 20, : object 'viridis' not found


